Workbook

Sheet ALL_DATA
A1: Sample_ID | B1: Site | C1: Season | D1: Typology | E1: Replicate | F1: Localisation_X | G1: Localisation_Y | H1: Date | I1: Heure | J1: Sediment_temperature | K1: pH | L1: Salinity | M1: Conductivity | N1: RedOx | O1: COD | P1: Bacteria | Q1: Nematoda | R1: Copepoda | S1: Ostracoda | T1: Total_meiofauna | U1: Chlorophyll_a | V1: Pheopigment | W1: Active_chlorophyll_a | X1: Al | Y1: As | Z1: Cd | AA1: Co | AB1: Cr | AC1: Cu | AD1: Fe | AE1: Mn | AF1: Ni | AG1: Pb | AH1: Se | AI1: V | AJ1: Zn | AK1: Ag | AL1: NO3 | AM1: NO2 | AN1: PO4 | AO1: Si | AP1: NH4 | AQ1: Total_Hydrocarbon | AR1: 1,3,5-TriCB | AS1: 1,2,4-TriCB | AT1: 1,2,3-TriCB | AU1: HCBD | AV1: Dichlorvos | AW1: PeCBz | AX1: a-HCH | AY1: HCB | AZ1: g-HCH | BA1: b-HCH | BB1: d-HCH | BC1: Heptachlor | BD1: 2,4'-Dicofol | BE1: oxychlordane | BF1: 4,4'-Dicofol | BG1: Heptachlor epoxyde cis | BH1: Heptachlor epoxyde trans | BI1: o,p-DDE | BJ1: g-chlordane | BK1: Trans nanochlor | BL1: a-endosulfan | BM1: a-chlordane | BN1: p,p-DDE | BO1: Dieldrin | BP1: o,p-DDD | BQ1: o,p-DDT | BR1: Endrin | BS1: cis-nanochlor | BT1: b-endosulfan | BU1: p,p-DDD | BV1: quinoxyfen | BW1: p,p-DDT | BX1: endosulfan sulfate | BY1: mirex | BZ1: cypermethrine | CA1: Water_content | CB1: D10 | CC1: D50 | CD1: D90 | CE1: Clay | CF1: Silt | CG1: Sand
A2: ST6_A20_1 | B2: ST6 | C2: AUTUMN_2020 | D2: FRESHWATER | E2: 1 | F2: 46.28213 | G2: -0.969368 | H2: 44167 | I2: 0.36111111 | J2: 6.2 | K2: 7.407 | L2: 0.5 | M2: 1.229 | N2: -19.5 | O2: 6.3 | P2: 1.2694575e+09 | Q2: 0.73333333 | R2: 0.74166667 | S2: 0.21666667 | T2: 1.9555556 | U2: 5.5615616 | V2: 23.805191 | W2: =U2/(U2+V2)*100 -> 18.938293 | X2: 6763.3198 | Y2: 10.733445 | Z2: 0.087067657 | AA2: 9.0583513 | AB2: 26.28924 | AC2: 11.11848 | AD2: 19054.817 | AE2: 390.10304 | AF2: 20.400791 | AG2: 34.287882 | AH2: 1.6978193 | AI2: 32.452073 | AJ2: 89.532111 | AK2: 0.063703171 | AL2: 0.03 | AM2: 0.49 | AN2: 1.75 | AO2: 401.49 | AP2: 150.51 | AQ2: 29.511799 | AR2: < 0.008 | AS2: < 2.988 | AT2: < 0.061 | AU2: < 0.312 | AV2: < 0.015 | AW2: < 0.056 | AX2: < 2.376 | AY2: < 0.005 | AZ2: < 0.477 | BA2: < 0.040 | BB2: < 0.166 | BC2: < 0.004 | BD2: < 0.049 | BE2: < 0.048 | BF2: < 0.049 | BG2: < 0.009 | BH2: < 0.027 | BI2: < 0.004 | BJ2: < 0.008 | BK2: < 0.009 | BL2: < 0.068 | BM2: < 0.007 | BN2: < 0.068 | BO2: < 0.025 | BP2: < 0.009 | BQ2: < 0.027 | BR2: < 0.016 | BS2: < 0.009 | BT2: < 0.067 | BU2: < 0.010 | BV2: < 0.017 | BW2: < 0.029 | BX2: < 0.013 | BY2: < 0.097 | BZ2: 0.026 | CA2: 61.254649 | CB2: 3.569 | CC2: 113.444 | CD2: 1012.508 | CE2: 3.923251 | CF2: 38.433541 | CG2: 57.643209
A3: ST6_A20_2 | B3: ST6 | C3: AUTUMN_2020 | D3: FRESHWATER | E3: 2 | F3: 46.28213 | G3: -0.969368 | H3: 44167 | I3: 0.37430556 | J3: 6.2 | K3: 7.572 | L3: 0.5 | M3: 1.253 | N3: -28.7 | O3: 8.4 | P3: 6.7910564e+08 | Q3: 0.7 | R3: 0.86666667 | S3: 2.0333333 | T3: 3.9888889 | U3: 3.4146341 | V3: 14.130526 | W3: =U3/(U3+V3)*100 -> 19.461972 | X3: 6624.35 | Y3: 7.7854811 | Z3: 0.057237293 | AA3: 8.2114152 | AB3: 22.281229 | AC3: 10.457959 | AD3: 17619.17 | AE3: 390.51352 | AF3: 18.357108 | AG3: 34.846225 | AH3: 1.2584143 | AI3: 25.77089 | AJ3: 72.508162 | AK3: 0.054617276 | AL3: 0.03 | AM3: 0.52 | AN3: 1.82 | AO3: 404.13 | AP3: 199 | AQ3: 32.660733 | AR3: < 0.008 | AS3: < 2.988 | AT3: < 0.061 | AU3: < 0.312 | AV3: < 0.015 | AW3: < 0.056 | AX3: < 2.376 | AY3: < 0.005 | AZ3: < 0.477 | BA3: < 0.040 | BB3: < 0.166 | BC3: < 0.004 | BD3: < 0.049 | BE3: < 0.048 | BF3: < 0.049 | BG3: < 0.009 | BH3: < 0.027 | BI3: < 0.004 | BJ3: < 0.008 | BK3: < 0.009 | BL3: < 0.068 | BM3: < 0.007 | BN3: < 0.068 | BO3: < 0.025 | BP3: < 0.009 | BQ3: < 0.027 | BR3: < 0.016 | BS3: < 0.009 | BT3: < 0.067 | BU3: < 0.010 | BV3: < 0.017 | BW3: < 0.029 | BX3: < 0.013 | BY3: < 0.097 | BZ3: 0.026 | CA3: 46.677321 | CB3: 2.003 | CC3: 8.423 | CD3: 44.289 | CE3: 8.331711 | CF3: 82.054848 | CG3: 9.613442
A4: ST6_A20_3 | B4: ST6 | C4: AUTUMN_2020 | D4: FRESHWATER | E4: 3 | F4: 46.28213 | G4: -0.969368 | H4: 44167 | I4: 0.37777778 | J4: 6.4 | K4: 7.404 | L4: 0.6 | M4: 1.218 | N4: -19.2 | O4: 6.3 | P4: 4.8704811e+08 | Q4: 4.1333333 | R4: 1.4 | S4: 2.2666667 | T4: 9.8444444 | U4: 19.737143 | V4: 20.940234 | W4: =U4/(U4+V4)*100 -> 48.521178 | X4: 6462.7048 | Y4: 7.1143341 | Z4: 0.071764927 | AA4: 9.0172726 | AB4: 26.617819 | AC4: 10.311189 | AD4: 18829.911 | AE4: 396.56621 | AF4: 20.157468 | AG4: 32.925221 | AH4: 1.566585 | AI4: 31.377849 | AJ4: 82.510454 | AK4: 0.057072895 | AL4: 0.01 | AM4: 3.09 | AN4: 1.37 | AO4: 448.72 | AP4: 170.92 | AQ4: 23.690862 | AR4: < 0.008 | AS4: < 2.988 | AT4: < 0.061 | AU4: < 0.312 | AV4: < 0.015 | AW4: < 0.056 | AX4: < 2.376 | AY4: < 0.005 | AZ4: < 0.477 | BA4: < 0.040 | BB4: < 0.166 | BC4: < 0.004 | BD4: < 0.049 | BE4: < 0.048 | BF4: < 0.049 | BG4: < 0.009 | BH4: < 0.027 | BI4: < 0.004 | BJ4: < 0.008 | BK4: < 0.009 | BL4: < 0.068 | BM4: < 0.007 | BN4: < 0.068 | BO4: < 0.025 | BP4: < 0.009 | BQ4: < 0.027 | BR4: < 0.016 | BS4: < 0.009 | BT4: < 0.067 | BU4: < 0.010 | BV4: < 0.017 | BW4: < 0.029 | BX4: < 0.013 | BY4: < 0.097 | BZ4: 0.026 | CA4: 63.770702 | CB4: 1.831 | CC4: 8.985 | CD4: 168.178 | CE4: 9.683883 | CF4: 69.547775 | CG4: 20.768343
A5: ST75_A20_1 | B5: St75 | C5: AUTUMN_2020 | D5: BRACKISH | E5: 1 | F5: 45.883995 | G5: -1.055508 | H5: 44168 | I5: 0.41666667 | J5: 7.2 | K5: 7.296 | L5: 2.5 | M5: 4.68 | N5: -13.6 | O5: 15 | P5: 8.7132265e+08 | Q5: 4 | R5: 24.666667 | S5: 1.1333333 | T5: 33 | U5: 14.74359 | V5: 50.722859 | W5: =U5/(U5+V5)*100 -> 22.520833 | X5: 6989.0353 | Y5: 19.680938 | Z5: 0.080976366 | AA5: 12.631364 | AB5: 31.562573 | AC5: 14.70308 | AD5: 24678.419 | AE5: 621.9721 | AF5: 25.750291 | AG5: 43.800852 | AH5: 1.588919 | AI5: 44.953119 | AJ5: 95.902945 | AK5: 0.069740411 | AL5: 0.03 | AM5: 0.23 | AN5: 4.6 | AO5: 359.04 | AP5: 236.44 | AQ5: 41.181218 | AR5: < 0.019 | AS5: < 2.399 | AT5: < 0.059 | AU5: < 0.311 | AV5: < 0.019 | AW5: < 0.054 | AX5: < 2.502 | AY5: < 0.007 | AZ5: < 0.467 | BA5: < 0.029 | BB5: < 0.118 | BC5: < 0.004 | BD5: < 0.030 | BE5: < 0.048 | BF5: < 0.049 | BG5: < 0.010 | BH5: < 0.028 | BI5: < 0.004 | BJ5: < 0.009 | BK5: < 0.010 | BL5: < 0.087 | BM5: < 0.009 | BN5: 0.033 | BO5: < 0.013 | BP5: < 0.015 | BQ5: < 0.029 | BR5: < 0.015 | BS5: < 0.009 | BT5: < 0.017 | BU5: < 0.010 | BV5: < 0.018 | BW5: < 0.027 | BX5: < 0.015 | BY5: < 0.100 | BZ5: < 0.023 | CA5: 66.387626 | CB5: 1.993 | CC5: 9.491 | CD5: 51.857 | CE5: 8.41268 | CF5: 80.168641 | CG5: 11.418678
A6: ST75_A20_2 | B6: St75 | C6: AUTUMN_2020 | D6: BRACKISH | E6: 2 | F6: 45.883995 | G6: -1.055508 | H6: 44168 | I6: 0.42708333 | J6: 7.6 | K6: 7.343 | L6: 2.4 | M6: 4.63 | N6: -16 | O6: 16 | P6: 7.0088977e+08 | Q6: 5.3333333 | R6: 19.666667 | S6: 1.8 | T6: 28.888889 | U6: 21.414141 | V6: 51.31586 | W6: =U6/(U6+V6)*100 -> 29.44334 | X6: 6584.9363 | Y6: 19.344089 | Z6: 0.080300763 | AA6: 12.203453 | AB6: 29.808921 | AC6: 13.995127 | AD6: 23400.737 | AE6: 656.19228 | AF6: 24.646312 | AG6: 42.249151 | AH6: 1.4591014 | AI6: 43.237581 | AJ6: 91.401978 | AK6: 0.065518122 | AL6: 0.11 | AM6: 0.2 | AN6: 3.73 | AO6: 344.12 | AP6: 243.68 | AQ6: 24.602564 | AR6: < 0.019 | AS6: < 2.399 | AT6: < 0.059 | AU6: < 0.311 | AV6: < 0.019 | AW6: < 0.054 | AX6: < 2.502 | AY6: < 0.007 | AZ6: < 0.467 | BA6: < 0.029 | BB6: < 0.118 | BC6: < 0.004 | BD6: < 0.030 | BE6: < 0.048 | BF6: < 0.049 | BG6: < 0.010 | BH6: < 0.028 | BI6: < 0.004 | BJ6: < 0.009 | BK6: < 0.010 | BL6: < 0.087 | BM6: < 0.009 | BN6: 0.033 | BO6: < 0.013 | BP6: < 0.015 | BQ6: < 0.029 | BR6: < 0.015 | BS6: < 0.009 | BT6: < 0.017 | BU6: < 0.010 | BV6: < 0.018 | BW6: < 0.027 | BX6: < 0.015 | BY6: < 0.100 | BZ6: < 0.023 | CA6: 67.788985 | CB6: 2.073 | CC6: 8.446 | CD6: 84.946 | CE6: 7.8165 | CF6: 77.493976 | CG6: 14.689523
A7: ST75_A20_3 | B7: St75 | C7: AUTUMN_2020 | D7: BRACKISH | E7: 3 | F7: 45.883995 | G7: -1.055508 | H7: 44168 | I7: 0.43402778 | J7: 7.5 | K7: 7.191 | L7: 2.4 | M7: 4.53 | N7: -7.7 | O7: 17 | P7: 1.1362379e+09 | Q7: 2.7333333 | R7: 21.933333 | S7: 1.6666667 | T7: 28.866667 | U7: 15.736132 | V7: 60.286647 | W7: =U7/(U7+V7)*100 -> 20.699233 | X7: 4317.9675 | Y7: 20.668985 | Z7: 0.088318747 | AA7: 11.976382 | AB7: 31.050633 | AC7: 14.033729 | AD7: 24973.424 | AE7: 621.18051 | AF7: 24.971027 | AG7: 44.11941 | AH7: 1.546777 | AI7: 44.084642 | AJ7: 97.393198 | AK7: 0.07353235 | AL7: 0.03 | AM7: 0.13 | AN7: 4.14 | AO7: 451.89 | AP7: 340.53 | AQ7: 34.236913 | AR7: < 0.019 | AS7: < 2.399 | AT7: < 0.059 | AU7: < 0.311 | AV7: < 0.019 | AW7: < 0.054 | AX7: < 2.502 | AY7: < 0.007 | AZ7: < 0.467 | BA7: < 0.029 | BB7: < 0.118 | BC7: < 0.004 | BD7: < 0.030 | BE7: < 0.048 | BF7: < 0.049 | BG7: < 0.010 | BH7: < 0.028 | BI7: < 0.004 | BJ7: < 0.009 | BK7: < 0.010 | BL7: < 0.087 | BM7: < 0.009 | BN7: 0.033 | BO7: < 0.013 | BP7: < 0.015 | BQ7: < 0.029 | BR7: < 0.015 | BS7: < 0.009 | BT7: < 0.017 | BU7: < 0.010 | BV7: < 0.018 | BW7: < 0.027 | BX7: < 0.015 | BY7: < 0.100 | BZ7: < 0.023 | CA7: 67.674852 | CB7: 1.818 | CC7: 7.6 | CD7: 39.043 | CE7: 9.78876 | CF7: 81.750908 | CG7: 8.460333
A8: ST16_A20_1 | B8: ST16 | C8: AUTUMN_2020 | D8: SALTED | E8: 1 | F8: 46.23537 | G8: -1.514997 | H8: 44162 | I8: 0.38888889 | J8: 10.3 | K8: 7.663 | L8: 33.7 | M8: 52 | N8: -34.1 | O8: 6.9 | P8: 1.7209701e+09 | Q8: 43.333333 | R8: 4.8 | S8: 3.7333333 | T8: 52.533333 | U8: 8.6777409 | V8: 10.010388 | W8: =U8/(U8+V8)*100 -> 46.43451 | X8: 4022.9425 | Y8: 7.9451844 | Z8: 0.086419278 | AA8: 4.3093194 | AB8: 13.562245 | AC8: 6.4935715 | AD8: 10281.969 | AE8: 148.7653 | AF8: 8.4551544 | AG8: 15.823004 | AH8: 1.0864963 | AI8: 19.154862 | AJ8: 92.092925 | AK8: 0.040226345 | AL8: 0 | AM8: 0.85 | AN8: 16.86 | AO8: 242.46 | AP8: 208.32 | AQ8: 39.612335 | AR8: 0.009 | AS8: < 2.794 | AT8: < 0.057 | AU8: < 0.292 | AV8: < 0.014 | AW8: < 0.052 | AX8: < 2.222 | AY8: < 0.005 | AZ8: < 0.446 | BA8: < 0.037 | BB8: < 0.155 | BC8: < 0.004 | BD8: < 0.046 | BE8: < 0.045 | BF8: 0.068 | BG8: < 0.009 | BH8: < 0.025 | BI8: < 0.004 | BJ8: < 0.007 | BK8: < 0.009 | BL8: < 0.064 | BM8: < 0.007 | BN8: < 0.063 | BO8: < 0.024 | BP8: 0.01 | BQ8: < 0.025 | BR8: < 0.015 | BS8: < 0.008 | BT8: < 0.063 | BU8: 0.03 | BV8: < 0.016 | BW8: < 0.027 | BX8: < 0.012 | BY8: < 0.091 | BZ8: < 0.015 | CA8: 43.367648 | CB8: 2.486 | CC8: 10.581 | CD8: 133.865 | CE8: 5.769831 | CF8: 68.995128 | CG8: 25.23504
A9: ST16_A20_2 | B9: ST16 | C9: AUTUMN_2020 | D9: SALTED | E9: 2 | F9: 46.23537 | G9: -1.514997 | H9: 44162 | I9: 0.39930556 | J9: 10.3 | K9: 7.721 | L9: 25.6 | M9: 40.6 | N9: -37.3 | O9: 8.7 | P9: 8.9517425e+08 | Q9: 19.6 | R9: 0.66666667 | S9: 2.5333333 | T9: 23.733333 | U9: 3.7350993 | V9: 2.4781229 | W9: =U9/(U9+V9)*100 -> 60.115335 | X9: 3445.5165 | Y9: 8.1238056 | Z9: 0.034473714 | AA9: 3.2368944 | AB9: 8.9922622 | AC9: 4.5007307 | AD9: 9092.6668 | AE9: 123.32915 | AF9: 6.151422 | AG9: 10.926668 | AH9: 0.64750628 | AI9: 15.326095 | AJ9: 30.239068 | AK9: 0.025667928 | AL9: 0.41 | AM9: 1.54 | AN9: 6.26 | AO9: 67.6 | AP9: 155.64 | AQ9: 40.359541 | AR9: 0.009 | AS9: < 2.794 | AT9: < 0.057 | AU9: < 0.292 | AV9: < 0.014 | AW9: < 0.052 | AX9: < 2.222 | AY9: < 0.005 | AZ9: < 0.446 | BA9: < 0.037 | BB9: < 0.155 | BC9: < 0.004 | BD9: < 0.046 | BE9: < 0.045 | BF9: 0.068 | BG9: < 0.009 | BH9: < 0.025 | BI9: < 0.004 | BJ9: < 0.007 | BK9: < 0.009 | BL9: < 0.064 | BM9: < 0.007 | BN9: < 0.063 | BO9: < 0.024 | BP9: 0.01 | BQ9: < 0.025 | BR9: < 0.015 | BS9: < 0.008 | BT9: < 0.063 | BU9: 0.03 | BV9: < 0.016 | BW9: < 0.027 | BX9: < 0.012 | BY9: < 0.091 | BZ9: < 0.015 | CA9: 31.438475 | CB9: 2.179 | CC9: 10.157 | CD9: 121.439 | CE9: 7.295182 | CF9: 66.36494 | CG9: 26.339876
A10: ST16_A20_3 | B10: ST16 | C10: AUTUMN_2020 | D10: SALTED | E10: 3 | F10: 46.23537 | G10: -1.514997 | H10: 44162 | I10: 0.40902778 | J10: 10.2 | K10: 7.368 | L10: 34 | M10: 52.6 | N10: -17.6 | O10: 14 | P10: 2.6832101e+09 | Q10: 45.6 | R10: 9.3333333 | S10: 3.7333333 | T10: 60.2 | U10: 19.737143 | V10: 20.940234 | W10: =U10/(U10+V10)*100 -> 48.521178 | X10: 4657.9741 | Y10: 10.750139 | Z10: 0.076605541 | AA10: 4.8811225 | AB10: 15.497043 | AC10: 7.4514567 | AD10: 11924.982 | AE10: 171.55235 | AF10: 9.9347861 | AG10: 17.924903 | AH10: 1.0425101 | AI10: 22.180479 | AJ10: 51.79507 | AK10: 0.04187505 | AL10: 0 | AM10: 1.23 | AN10: 74.41 | AO10: 345.64 | AP10: 668.44 | AQ10: 25.190696 | AR10: 0.009 | AS10: < 2.794 | AT10: < 0.057 | AU10: < 0.292 | AV10: < 0.014 | AW10: < 0.052 | AX10: < 2.222 | AY10: < 0.005 | AZ10: < 0.446 | BA10: < 0.037 | BB10: < 0.155 | BC10: < 0.004 | BD10: < 0.046 | BE10: < 0.045 | BF10: 0.068 | BG10: < 0.009 | BH10: < 0.025 | BI10: < 0.004 | BJ10: < 0.007 | BK10: < 0.009 | BL10: < 0.064 | BM10: < 0.007 | BN10: < 0.063 | BO10: < 0.024 | BP10: 0.01 | BQ10: < 0.025 | BR10: < 0.015 | BS10: < 0.008 | BT10: < 0.063 | BU10: 0.03 | BV10: < 0.016 | BW10: < 0.027 | BX10: < 0.012 | BY10: < 0.091 | BZ10: < 0.015 | CA10: 48.309989 | CB10: 2.333 | CC10: 14.098 | CD10: 146.066 | CE10: 6.642665 | CF10: 59.627681 | CG10: 33.729655
A11: ST13_A20_1 | B11: ST13 | C11: AUTUMN_2020 | D11: BRACKISH | E11: 1 | F11: 46.262243 | G11: -1.106867 | H11: 44162 | I11: 0.46180556 | J11: 9.1 | K11: 7.538 | L11: 4.2 | M11: 7.76 | N11: -27.1 | O11: 6.8 | P11: 5.8123693e+08 | Q11: 2.4166667 | R11: 0.11666667 | S11: 0.18333333 | T11: 2.9666667 | U11: 7.8120411 | V11: 34.690566 | W11: =U11/(U11+V11)*100 -> 18.380146 | X11: 6111.072 | Y11: 18.272277 | Z11: 0.098465273 | AA11: 12.165492 | AB11: 33.388928 | AC11: 14.967074 | AD11: 23963.276 | AE11: 579.11479 | AF11: 24.541931 | AG11: 40.932582 | AH11: 1.871819 | AI11: 45.071255 | AJ11: 110.1936 | AK11: 0.07556182 | AL11: 0.14 | AM11: 0.412 | AN11: 9.66 | AO11: 571.54 | AP11: 458.852 | AQ11: 22.985833 | AR11: < 0.008 | AS11: < 3.048 | AT11: < 0.062 | AU11: < 0.319 | AV11: < 0.015 | AW11: < 0.057 | AX11: < 2.424 | AY11: < 0.005 | AZ11: < 0.486 | BA11: < 0.040 | BB11: < 0.169 | BC11: < 0.005 | BD11: < 0.050 | BE11: < 0.049 | BF11: 0.082 | BG11: < 0.010 | BH11: < 0.028 | BI11: < 0.004 | BJ11: < 0.008 | BK11: < 0.009 | BL11: < 0.070 | BM11: < 0.007 | BN11: 0.08 | BO11: < 0.026 | BP11: 0.017 | BQ11: < 0.028 | BR11: < 0.017 | BS11: < 0.009 | BT11: < 0.069 | BU11: 0.053 | BV11: < 0.018 | BW11: 0.051 | BX11: < 0.014 | BY11: < 0.099 | BZ11: < 0.016 | CA11: 66.060966 | CB11: 1.761 | CC11: 7.791 | CD11: 54.717 | CE11: 10.312037 | CF11: 78.266147 | CG11: 11.421816
A12: ST13_A20_2 | B12: ST13 | C12: AUTUMN_2020 | D12: BRACKISH | E12: 2 | F12: 46.262243 | G12: -1.106867 | H12: 44162 | I12: 0.47291667 | J12: 9.4 | K12: 7.511 | L12: 4.1 | M12: 7.45 | N12: -25.6 | O12: 8.4 | P12: 4.9817555e+08 | Q12: 1.2166667 | R12: 0.016666667 | S12: 0.033333333 | T12: 1.4111111 | U12: 6.4190801 | V12: 29.896291 | W12: =U12/(U12+V12)*100 -> 17.675932 | X12: 6325.9623 | Y12: 18.884885 | Z12: 0.09909411 | AA12: 12.365817 | AB12: 34.13802 | AC12: 15.303394 | AD12: 24481.783 | AE12: 569.3639 | AF12: 24.869655 | AG12: 42.70343 | AH12: 1.7635191 | AI12: 44.999011 | AJ12: 113.14411 | AK12: 0.080699395 | AL12: 0.81 | AM12: 0.23 | AN12: 19.66 | AO12: 424.96 | AP12: 498.56 | AQ12: 35.008846 | AR12: < 0.008 | AS12: < 3.048 | AT12: < 0.062 | AU12: < 0.319 | AV12: < 0.015 | AW12: < 0.057 | AX12: < 2.424 | AY12: < 0.005 | AZ12: < 0.486 | BA12: < 0.040 | BB12: < 0.169 | BC12: < 0.005 | BD12: < 0.050 | BE12: < 0.049 | BF12: 0.082 | BG12: < 0.010 | BH12: < 0.028 | BI12: < 0.004 | BJ12: < 0.008 | BK12: < 0.009 | BL12: < 0.070 | BM12: < 0.007 | BN12: 0.08 | BO12: < 0.026 | BP12: 0.017 | BQ12: < 0.028 | BR12: < 0.017 | BS12: < 0.009 | BT12: < 0.069 | BU12: 0.053 | BV12: < 0.018 | BW12: 0.051 | BX12: < 0.014 | BY12: < 0.099 | BZ12: < 0.016 | CA12: 65.14999 | CB12: 1.795 | CC12: 7.11 | CD12: 27.464 | CE12: 10.000335 | CF12: 85.976727 | CG12: 4.022935
A13: ST13_A20_3 | B13: ST13 | C13: AUTUMN_2020 | D13: BRACKISH | E13: 3 | F13: 46.262243 | G13: -1.106867 | H13: 44162 | I13: 0.48194444 | J13: 9.5 | K13: 7.445 | L13: 4.3 | M13: 7.8 | N13: -21.9 | O13: 8.6 | P13: 5.9800338e+08 | Q13: 2.85 | R13: 0.18333333 | S13: 0.05 | T13: 3.3055556 | U13: 6.8025478 | V13: 30.446015 | W13: =U13/(U13+V13)*100 -> 18.262578 | X13: 6604.7385 | Y13: 19.094324 | Z13: 0.10821017 | AA13: 12.456716 | AB13: 34.837583 | AC13: 14.959822 | AD13: 24582.792 | AE13: 584.22527 | AF13: 25.488062 | AG13: 44.014942 | AH13: 1.6838558 | AI13: 46.050836 | AJ13: 113.0173 | AK13: 0.084862758 | AL13: 0.66 | AM13: 0.29 | AN13: 12.62 | AO13: 539.62 | AP13: 507.5 | AQ13: 25.104131 | AR13: < 0.008 | AS13: < 3.048 | AT13: < 0.062 | AU13: < 0.319 | AV13: < 0.015 | AW13: < 0.057 | AX13: < 2.424 | AY13: < 0.005 | AZ13: < 0.486 | BA13: < 0.040 | BB13: < 0.169 | BC13: < 0.005 | BD13: < 0.050 | BE13: < 0.049 | BF13: 0.082 | BG13: < 0.010 | BH13: < 0.028 | BI13: < 0.004 | BJ13: < 0.008 | BK13: < 0.009 | BL13: < 0.070 | BM13: < 0.007 | BN13: 0.08 | BO13: < 0.026 | BP13: 0.017 | BQ13: < 0.028 | BR13: < 0.017 | BS13: < 0.009 | BT13: < 0.069 | BU13: 0.053 | BV13: < 0.018 | BW13: 0.051 | BX13: < 0.014 | BY13: < 0.099 | BZ13: < 0.016 | CA13: 67.176939 | CB13: 1.768 | CC13: 8.689 | CD13: 97.85 | CE13: 10.241711 | CF13: 73.913161 | CG13: 15.84513
A14: ST52_A20_1 | B14: ST52 | C14: AUTUMN_2020 | D14: SALTED | E14: 1 | F14: 45.961839 | G14: -1.278105 | H14: 44165 | I14: 0.40625 | J14: 5.6 | K14: 7.693 | L14: 32.8 | M14: 50.5 | N14: -35.8 | O14: 14 | P14: 1649960000 | Q14: 33.466667 | R14: 2.1333333 | S14: 1.8666667 | T14: 39.733333 | U14: 6.6646059 | V14: 13.216726 | W14: =U14/(U14+V14)*100 -> 33.521928 | X14: 6368.8774 | Y14: 12.679362 | Z14: 0.076494854 | AA14: 8.7837519 | AB14: 24.052025 | AC14: 12.184549 | AD14: 18384.417 | AE14: 261.54632 | AF14: 17.205415 | AG14: 36.365093 | AH14: 1.3656935 | AI14: 31.495254 | AJ14: 92.626857 | AK14: 0.06868517 | AL14: 0 | AM14: 1.23 | AN14: 7.65 | AO14: 125.01 | AP14: 105.23 | AQ14: 38.001032 | AR14: < 0.008 | AS14: < 2.874 | AT14: < 0.058 | AU14: < 0.300 | AV14: < 0.014 | AW14: < 0.054 | AX14: < 2.285 | AY14: < 0.005 | AZ14: < 0.459 | BA14: < 0.038 | BB14: < 0.159 | BC14: < 0.004 | BD14: 0.063 | BE14: < 0.046 | BF14: 0.147 | BG14: < 0.009 | BH14: < 0.026 | BI14: < 0.004 | BJ14: < 0.008 | BK14: < 0.009 | BL14: < 0.066 | BM14: < 0.007 | BN14: 0.143 | BO14: < 0.024 | BP14: 0.042 | BQ14: 0.039 | BR14: < 0.016 | BS14: < 0.008 | BT14: < 0.065 | BU14: 0.092 | BV14: < 0.017 | BW14: 0.155 | BX14: < 0.013 | BY14: < 0.094 | BZ14: < 0.015 | CA14: 45.313201 | CB14: 2.164 | CC14: 12.18 | CD14: 130.864 | CE14: 7.312817 | CF14: 63.767315 | CG14: 28.919865
A15: ST52_A20_2 | B15: ST52 | C15: AUTUMN_2020 | D15: SALTED | E15: 2 | F15: 45.961839 | G15: -1.278105 | H15: 44165 | I15: 0.41319444 | J15: 6.2 | K15: 7.664 | L15: 32.3 | M15: 49.8 | N15: -34.1 | O15: 11 | P15: 1.5782226e+09 | Q15: 42 | R15: 2.5333333 | S15: 0.93333333 | T15: 49.2 | U15: 8.3977055 | V15: 14.36862 | W15: =U15/(U15+V15)*100 -> 36.886521 | X15: 6111.8439 | Y15: 10.728757 | Z15: 0.073779796 | AA15: 7.7608321 | AB15: 21.130573 | AC15: 11.617578 | AD15: 16264.394 | AE15: 266.15327 | AF15: 15.049141 | AG15: 31.018827 | AH15: 1.2759795 | AI15: 27.884653 | AJ15: 78.382911 | AK15: 0.064190379 | AL15: 0.24 | AM15: 0.96 | AN15: 5.31 | AO15: 99.61 | AP15: 93.67 | AQ15: 51.350018 | AR15: < 0.008 | AS15: < 2.874 | AT15: < 0.058 | AU15: < 0.300 | AV15: < 0.014 | AW15: < 0.054 | AX15: < 2.285 | AY15: < 0.005 | AZ15: < 0.459 | BA15: < 0.038 | BB15: < 0.159 | BC15: < 0.004 | BD15: 0.063 | BE15: < 0.046 | BF15: 0.147 | BG15: < 0.009 | BH15: < 0.026 | BI15: < 0.004 | BJ15: < 0.008 | BK15: < 0.009 | BL15: < 0.066 | BM15: < 0.007 | BN15: 0.143 | BO15: < 0.024 | BP15: 0.042 | BQ15: 0.039 | BR15: < 0.016 | BS15: < 0.008 | BT15: < 0.065 | BU15: 0.092 | BV15: < 0.017 | BW15: 0.155 | BX15: < 0.013 | BY15: < 0.094 | BZ15: < 0.015 | CA15: 45.632946 | CB15: 2.358 | CC15: 12.082 | CD15: 121.772 | CE15: 6.362219 | CF15: 65.529058 | CG15: 28.108724
A16: ST52_A20_3 | B16: ST52 | C16: AUTUMN_2020 | D16: SALTED | E16: 3 | F16: 45.961839 | G16: -1.278105 | H16: 44165 | I16: 0.42013889 | J16: 5.6 | K16: 7.636 | L16: 32.6 | M16: 50.6 | N16: -32.6 | O16: 7.3 | P16: 1.6454496e+09 | Q16: 55.6 | R16: 3.8666667 | S16: 2.5333333 | T16: 66.133333 | U16: 10.128755 | V16: 16.089043 | W16: =U16/(U16+V16)*100 -> 38.633127 | X16: 6177.4112 | Y16: 11.378768 | Z16: 0.070590071 | AA16: 7.7455637 | AB16: 21.344331 | AC16: 10.138723 | AD16: 16331.013 | AE16: 279.93838 | AF16: 15.211361 | AG16: 30.966031 | AH16: 1.1545962 | AI16: 27.966928 | AJ16: 78.811669 | AK16: 0.063765064 | AL16: 0 | AM16: 1.17 | AN16: 4.66 | AO16: 95.19 | AP16: 75.02 | AQ16: 39.903372 | AR16: < 0.008 | AS16: < 2.874 | AT16: < 0.058 | AU16: < 0.300 | AV16: < 0.014 | AW16: < 0.054 | AX16: < 2.285 | AY16: < 0.005 | AZ16: < 0.459 | BA16: < 0.038 | BB16: < 0.159 | BC16: < 0.004 | BD16: 0.063 | BE16: < 0.046 | BF16: 0.147 | BG16: < 0.009 | BH16: < 0.026 | BI16: < 0.004 | BJ16: < 0.008 | BK16: < 0.009 | BL16: < 0.066 | BM16: < 0.007 | BN16: 0.143 | BO16: < 0.024 | BP16: 0.042 | BQ16: 0.039 | BR16: < 0.016 | BS16: < 0.008 | BT16: < 0.065 | BU16: 0.092 | BV16: < 0.017 | BW16: 0.155 | BX16: < 0.013 | BY16: < 0.094 | BZ16: < 0.015 | CA16: 41.616083 | CB16: 2.11 | CC16: 8.852 | CD16: 80.138 | CE16: 7.585194 | CF16: 75.13928 | CG16: 17.275526
A17: ST61_A20_1 | B17: ST61 | C17: AUTUMN_2020 | D17: SALTED | E17: 1 | F17: 45.771769 | G17: -1.054261 | H17: 44165 | I17: 0.47916667 | J17: 5.5 | K17: 7.931 | L17: 31 | M17: =1.554*L17+0.4349 -> 48.6089 | N17: -49 | O17: 8.9 | P17: 6.3060174e+08 | Q17: 8.4 | R17: 3.1333333 | S17: 0.93333333 | T17: 13.422222 | U17: 1.5407407 | V17: 6.7447484 | W17: =U17/(U17+V17)*100 -> 18.595652 | X17: 6590.0792 | Y17: 20.469381 | Z17: 0.083818064 | AA17: 12.677755 | AB17: 29.034174 | AC17: 15.614114 | AD17: 23837.05 | AE17: 614.22483 | AF17: 24.855389 | AG17: 35.809501 | AH17: 1.7821942 | AI17: 43.872799 | AJ17: 84.277145 | AK17: 0.080788496 | AL17: 0 | AM17: 2.28 | AN17: 7.03 | AO17: 125.08 | AP17: 211.5 | AQ17: 21.479793 | AR17: < 0.018 | AS17: < 2.307 | AT17: < 0.057 | AU17: < 0.299 | AV17: < 0.018 | AW17: < 0.052 | AX17: < 2.406 | AY17: < 0.007 | AZ17: < 0.449 | BA17: < 0.028 | BB17: < 0.113 | BC17: < 0.004 | BD17: 0.036 | BE17: < 0.046 | BF17: 0.074 | BG17: < 0.009 | BH17: < 0.027 | BI17: 0.005 | BJ17: < 0.009 | BK17: < 0.009 | BL17: < 0.084 | BM17: < 0.009 | BN17: 0.106 | BO17: < 0.013 | BP17: 0.039 | BQ17: < 0.028 | BR17: < 0.014 | BS17: < 0.009 | BT17: < 0.016 | BU17: 0.11 | BV17: < 0.018 | BW17: 0.098 | BX17: < 0.015 | BY17: < 0.096 | BZ17: < 0.022 | CA17: 49.221361 | CB17: 2.139 | CC17: 8.567 | CD17: 70.883 | CE17: 7.421617 | CF17: 78.182019 | CG17: 14.396366
A18: ST61_A20_2 | B18: ST61 | C18: AUTUMN_2020 | D18: SALTED | E18: 2 | F18: 45.771769 | G18: -1.054261 | H18: 44165 | I18: 0.48263889 | J18: 6.1 | K18: 8.036 | L18: 32 | M18: =1.554*L18+0.4349 -> 50.1629 | N18: -54.9 | O18: 7.5 | P18: 9.7597217e+08 | Q18: 8.1333333 | R18: 3.1333333 | S18: 0.53333333 | T18: 12.555556 | U18: 1.2823529 | V18: 7.1329281 | W18: =U18/(U18+V18)*100 -> 15.238385 | X18: 6521.5351 | Y18: 22.807617 | Z18: 0.087357676 | AA18: 12.584747 | AB18: 28.745387 | AC18: 14.684865 | AD18: 23794.464 | AE18: 510.87947 | AF18: 24.413035 | AG18: 37.161366 | AH18: 1.8091873 | AI18: 45.101885 | AJ18: 83.719474 | AK18: 0.086572438 | AL18: 1.12 | AM18: 2.29 | AN18: 7.2 | AO18: 125.33 | AP18: 262.76 | AQ18: 74.751472 | AR18: < 0.018 | AS18: < 2.307 | AT18: < 0.057 | AU18: < 0.299 | AV18: < 0.018 | AW18: < 0.052 | AX18: < 2.406 | AY18: < 0.007 | AZ18: < 0.449 | BA18: < 0.028 | BB18: < 0.113 | BC18: < 0.004 | BD18: 0.036 | BE18: < 0.046 | BF18: 0.074 | BG18: < 0.009 | BH18: < 0.027 | BI18: 0.005 | BJ18: < 0.009 | BK18: < 0.009 | BL18: < 0.084 | BM18: < 0.009 | BN18: 0.106 | BO18: < 0.013 | BP18: 0.039 | BQ18: < 0.028 | BR18: < 0.014 | BS18: < 0.009 | BT18: < 0.016 | BU18: 0.11 | BV18: < 0.018 | BW18: 0.098 | BX18: < 0.015 | BY18: < 0.096 | BZ18: < 0.022 | CA18: 48.875626 | CB18: 1.844 | CC18: 7.862 | CD18: 305.097 | CE18: 9.557938 | CF18: 70.537252 | CG18: 19.904808
A19: ST61_A20_3 | B19: ST61 | C19: AUTUMN_2020 | D19: SALTED | E19: 3 | F19: 45.771769 | G19: -1.054261 | H19: 44165 | I19: 0.48611111 | J19: 6 | K19: 8.043 | L19: 32 | M19: =1.554*L19+0.4349 -> 50.1629 | N19: -55.3 | O19: 37 | P19: 6.4993217e+08 | Q19: 7 | R19: 3.2666667 | S19: 0.46666667 | T19: 11.611111 | U19: 1.5445545 | V19: 6.6544417 | W19: =U19/(U19+V19)*100 -> 18.838336 | X19: 6609.5918 | Y19: 18.81206 | Z19: 0.095798386 | AA19: 12.435903 | AB19: 27.9618 | AC19: 13.885141 | AD19: 22782.327 | AE19: 566.52224 | AF19: 23.767739 | AG19: 36.451087 | AH19: 1.6347339 | AI19: 44.207974 | AJ19: 82.552172 | AK19: 0.080494495 | AL19: 0 | AM19: 5.74 | AN19: 14.54 | AO19: 168.95 | AP19: 297.12 | AQ19: 27.475884 | AR19: < 0.018 | AS19: < 2.307 | AT19: < 0.057 | AU19: < 0.299 | AV19: < 0.018 | AW19: < 0.052 | AX19: < 2.406 | AY19: < 0.007 | AZ19: < 0.449 | BA19: < 0.028 | BB19: < 0.113 | BC19: < 0.004 | BD19: 0.036 | BE19: < 0.046 | BF19: 0.074 | BG19: < 0.009 | BH19: < 0.027 | BI19: 0.005 | BJ19: < 0.009 | BK19: < 0.009 | BL19: < 0.084 | BM19: < 0.009 | BN19: 0.106 | BO19: < 0.013 | BP19: 0.039 | BQ19: < 0.028 | BR19: < 0.014 | BS19: < 0.009 | BT19: < 0.016 | BU19: 0.11 | BV19: < 0.018 | BW19: 0.098 | BX19: < 0.015 | BY19: < 0.096 | BZ19: < 0.022 | CA19: 48.418654 | CB19: 2.011 | CC19: 7.789 | CD19: 49.851 | CE19: 8.223179 | CF19: 80.924443 | CG19: 10.852379
A20: ST63_A20_1 | B20: ST63 | C20: AUTUMN_2020 | D20: BRACKISH | E20: 1 | F20: 45.323742 | G20: -0.70269 | H20: 44172 | I20: 0.44791667 | J20: 6.4 | K20: 7.675 | L20: 6.3 | M20: 11.35 | N20: -36 | O20: =AVERAGE(O21:O22) -> 13.5 | P20: 99370342 | Q20: 9.6666667 | R20: 0 | S20: 0.13333333 | T20: 11.044444 | U20: 0.27963526 | V20: 0.4717744 | W20: =U20/(U20+V20)*100 -> 37.214754 | X20: 4405.4153 | Y20: 28.690752 | Z20: 0.10170604 | AA20: 13.127412 | AB20: 33.818898 | AC20: 19.737726 | AD20: 28329.474 | AE20: 356.82608 | AF20: 28.188204 | AG20: 33.966342 | AH20: 3.7150687 | AI20: 35.524355 | AJ20: 100.4406 | AK20: 0.12351397 | AL20: =AVERAGE(AL21:AL22) -> 0 | AM20: =AVERAGE(AM21:AM22) -> 0.65 | AN20: =AVERAGE(AN21:AN22) -> 8.68 | AO20: 194.17 | AP20: =AVERAGE(AP21:AP22) -> 175.45 | AQ20: 53.284497 | AR20: < 0.019 | AS20: < 2.448 | AT20: < 0.061 | AU20: < 0.317 | AV20: < 0.019 | AW20: < 0.055 | AX20: < 2.553 | AY20: < 0.007 | AZ20: < 0.476 | BA20: < 0.030 | BB20: < 0.120 | BC20: < 0.004 | BD20: 0.046 | BE20: < 0.049 | BF20: 0.086 | BG20: < 0.010 | BH20: < 0.028 | BI20: 0.004 | BJ20: < 0.009 | BK20: < 0.010 | BL20: < 0.089 | BM20: < 0.009 | BN20: 0.141 | BO20: < 0.014 | BP20: 0.028 | BQ20: < 0.029 | BR20: < 0.015 | BS20: < 0.010 | BT20: < 0.017 | BU20: 0.08 | BV20: < 0.019 | BW20: 0.112 | BX20: < 0.016 | BY20: < 0.102 | BZ20: 0.045 | CA20: 46.563377 | CB20: 1.653 | CC20: 6.122 | CD20: 34.891 | CE20: 11.558673 | CF20: 80.471885 | CG20: 7.969441
A21: ST63_A20_2 | B21: ST63 | C21: AUTUMN_2020 | D21: BRACKISH | E21: 2 | F21: 45.323742 | G21: -0.70269 | H21: 44172 | I21: 0.45625 | J21: 6.7 | K21: 7.698 | L21: 5 | M21: 8.9 | N21: -35.4 | O21: 13 | P21: 5.5478215e+08 | Q21: 12.533333 | R21: 0.33333333 | S21: 0.13333333 | T21: 14.644444 | U21: 1.889065 | V21: 7.385225 | W21: =U21/(U21+V21)*100 -> 20.368837 | X21: 4248.9134 | Y21: 18.487615 | Z21: 0.22693181 | AA21: 18.414516 | AB21: 29.091888 | AC21: 20.817339 | AD21: 23449.363 | AE21: 348.44994 | AF21: 29.641525 | AG21: 47.309512 | AH21: 2.7770299 | AI21: 33.67918 | AJ21: 152.65145 | AK21: 0.12462018 | AL21: 0 | AM21: 0.79 | AN21: 5.7 | AO21: 48.9 | AP21: 177.22 | AQ21: 26.787669 | AR21: < 0.019 | AS21: < 2.448 | AT21: < 0.061 | AU21: < 0.317 | AV21: < 0.019 | AW21: < 0.055 | AX21: < 2.553 | AY21: < 0.007 | AZ21: < 0.476 | BA21: < 0.030 | BB21: < 0.120 | BC21: < 0.004 | BD21: 0.046 | BE21: < 0.049 | BF21: 0.086 | BG21: < 0.010 | BH21: < 0.028 | BI21: 0.004 | BJ21: < 0.009 | BK21: < 0.010 | BL21: < 0.089 | BM21: < 0.009 | BN21: 0.141 | BO21: < 0.014 | BP21: 0.028 | BQ21: < 0.029 | BR21: < 0.015 | BS21: < 0.010 | BT21: < 0.017 | BU21: 0.08 | BV21: < 0.019 | BW21: 0.112 | BX21: < 0.016 | BY21: < 0.102 | BZ21: 0.045 | CA21: 45.255174 | CB21: 1.797 | CC21: 8.966 | CD21: 115.227 | CE21: 9.987153 | CF21: 73.005952 | CG21: 17.006896
A22: ST63_A20_3 | B22: ST63 | C22: AUTUMN_2020 | D22: BRACKISH | E22: 3 | F22: 45.323742 | G22: -0.70269 | H22: 44172 | I22: 0.46527778 | J22: 7.2 | K22: =AVERAGE(K20:K21) -> 7.6865 | L22: =AVERAGE(L20:L21) -> 5.65 | M22: =AVERAGE(M20:M21) -> 10.125 | N22: =AVERAGE(N20:N21) -> -35.7 | O22: 14 | P22: 9.612475e+08 | Q22: 8.4666667 | R22: 1.1333333 | S22: 0.2 | T22: 10.511111 | U22: 14.323575 | V22: 11.591128 | W22: =U22/(U22+V22)*100 -> 55.272 | X22: 4330.7742 | Y22: 21.382701 | Z22: 0.27022427 | AA22: 18.878144 | AB22: 40.083204 | AC22: 25.53799 | AD22: 28160.054 | AE22: 549.35895 | AF22: 34.058281 | AG22: 59.906963 | AH22: 3.0029121 | AI22: 40.83223 | AJ22: 187.40082 | AK22: 0.17453954 | AL22: 0 | AM22: 0.51 | AN22: 11.66 | AO22: 68.1 | AP22: 173.68 | AQ22: 19.703258 | AR22: < 0.019 | AS22: < 2.448 | AT22: < 0.061 | AU22: < 0.317 | AV22: < 0.019 | AW22: < 0.055 | AX22: < 2.553 | AY22: < 0.007 | AZ22: < 0.476 | BA22: < 0.030 | BB22: < 0.120 | BC22: < 0.004 | BD22: 0.046 | BE22: < 0.049 | BF22: 0.086 | BG22: < 0.010 | BH22: < 0.028 | BI22: 0.004 | BJ22: < 0.009 | BK22: < 0.010 | BL22: < 0.089 | BM22: < 0.009 | BN22: 0.141 | BO22: < 0.014 | BP22: 0.028 | BQ22: < 0.029 | BR22: < 0.015 | BS22: < 0.010 | BT22: < 0.017 | BU22: 0.08 | BV22: < 0.019 | BW22: 0.112 | BX22: < 0.016 | BY22: < 0.102 | BZ22: 0.045 | CA22: 65.839374 | CB22: 1.555 | CC22: 6.785 | CD22: 35.968 | CE22: 12.595853 | CF22: 79.653474 | CG22: 7.750669
A23: STRAPH_A20_1 | B23: STRAPH | C23: AUTUMN_2020 | D23: FRESHWATER | E23: 1 | F23: 45.996237 | G23: -0.793843 | H23: 44166 | I23: 0.39583333 | J23: 6.5 | K23: 7.254 | L23: 0.4 | M23: 0.975 | N23: -12.1 | O23: 11 | P23: 6.1923687e+08 | Q23: 0.88333333 | R23: 0.25 | S23: 0.13333333 | T23: 1.6277778 | U23: 18.501718 | V23: 41.132635 | W23: =U23/(U23+V23)*100 -> 31.025269 | X23: 7124.0953 | Y23: 14.936703 | Z23: 0.069175097 | AA23: 11.605242 | AB23: 32.020473 | AC23: 11.291235 | AD23: 24048.543 | AE23: 431.27474 | AF23: 25.177536 | AG23: 36.246951 | AH23: 2.0812507 | AI23: 35.549402 | AJ23: 98.125275 | AK23: 0.068375385 | AL23: 0 | AM23: 0.31 | AN23: 1.21 | AO23: 290.11 | AP23: 125.24 | AQ23: 57.184029 | AR23: < 0.018 | AS23: < 2.376 | AT23: < 0.059 | AU23: < 0.308 | AV23: < 0.018 | AW23: < 0.054 | AX23: < 2.477 | AY23: < 0.007 | AZ23: < 0.462 | BA23: < 0.029 | BB23: < 0.117 | BC23: < 0.004 | BD23: < 0.030 | BE23: < 0.048 | BF23: < 0.049 | BG23: < 0.009 | BH23: < 0.027 | BI23: < 0.004 | BJ23: < 0.009 | BK23: < 0.009 | BL23: < 0.086 | BM23: < 0.009 | BN23: 0.024 | BO23: < 0.013 | BP23: < 0.014 | BQ23: < 0.029 | BR23: < 0.015 | BS23: < 0.009 | BT23: < 0.017 | BU23: < 0.010 | BV23: < 0.018 | BW23: < 0.027 | BX23: < 0.015 | BY23: < 0.099 | BZ23: < 0.023 | CA23: 59.172059 | CB23: 2.046 | CC23: 9.243 | CD23: 49.442 | CE23: 8.055336 | CF23: 80.982892 | CG23: 10.961773
A24: STRAPH_A20_2 | B24: STRAPH | C24: AUTUMN_2020 | D24: FRESHWATER | E24: 2 | F24: 45.996237 | G24: -0.793843 | H24: 44166 | I24: 0.40625 | J24: 6.2 | K24: 7.212 | L24: 0.4 | M24: 1.032 | N24: -8.8 | O24: 12 | P24: 5.7598548e+08 | Q24: 2.2333333 | R24: 0.43333333 | S24: 0.76666667 | T24: 6.7222222 | U24: 18.900154 | V24: 43.054255 | W24: =U24/(U24+V24)*100 -> 30.506551 | X24: 6727.6687 | Y24: 11.298671 | Z24: 0.077159914 | AA24: 10.992491 | AB24: 31.460782 | AC24: 10.484042 | AD24: 22868.434 | AE24: 540.0612 | AF24: 24.221079 | AG24: 34.675027 | AH24: 2.2152968 | AI24: 34.663388 | AJ24: 98.687718 | AK24: 0.064393797 | AL24: 0.04 | AM24: 0.3 | AN24: 1.344 | AO24: 274.47 | AP24: 150.522 | AQ24: 39.374643 | AR24: < 0.018 | AS24: < 2.376 | AT24: < 0.059 | AU24: < 0.308 | AV24: < 0.018 | AW24: < 0.054 | AX24: < 2.477 | AY24: < 0.007 | AZ24: < 0.462 | BA24: < 0.029 | BB24: < 0.117 | BC24: < 0.004 | BD24: < 0.030 | BE24: < 0.048 | BF24: < 0.049 | BG24: < 0.009 | BH24: < 0.027 | BI24: < 0.004 | BJ24: < 0.009 | BK24: < 0.009 | BL24: < 0.086 | BM24: < 0.009 | BN24: 0.024 | BO24: < 0.013 | BP24: < 0.014 | BQ24: < 0.029 | BR24: < 0.015 | BS24: < 0.009 | BT24: < 0.017 | BU24: < 0.010 | BV24: < 0.018 | BW24: < 0.027 | BX24: < 0.015 | BY24: < 0.099 | BZ24: < 0.023 | CA24: 63.429721 | CB24: 2.008 | CC24: 7.615 | CD24: 33.398 | CE24: 8.196883 | CF24: 85.541286 | CG24: 6.261829
A25: STRAPH_A20_3 | B25: STRAPH | C25: AUTUMN_2020 | D25: FRESHWATER | E25: 3 | F25: 45.996237 | G25: -0.793843 | H25: 44166 | I25: 0.40972222 | J25: 6.6 | K25: 7.09 | L25: 0.4 | M25: 1.012 | N25: -2.2 | O25: 11 | P25: 6.0716362e+08 | Q25: 2.8666667 | R25: 0.6 | S25: 0.56666667 | T25: 6.1111111 | U25: 26.528363 | V25: 57.336598 | W25: =U25/(U25+V25)*100 -> 31.632237 | X25: 6531.8891 | Y25: 10.559008 | Z25: 0.069921226 | AA25: 11.087121 | AB25: 31.59265 | AC25: 10.675508 | AD25: 22451.037 | AE25: 445.96372 | AF25: 24.537111 | AG25: 31.50972 | AH25: 1.8735998 | AI25: 34.607032 | AJ25: 91.490749 | AK25: 0.062874901 | AL25: 0.05 | AM25: 0.27 | AN25: 0.986 | AO25: 282.19 | AP25: 193.904 | AQ25: 55.395747 | AR25: < 0.018 | AS25: < 2.376 | AT25: < 0.059 | AU25: < 0.308 | AV25: < 0.018 | AW25: < 0.054 | AX25: < 2.477 | AY25: < 0.007 | AZ25: < 0.462 | BA25: < 0.029 | BB25: < 0.117 | BC25: < 0.004 | BD25: < 0.030 | BE25: < 0.048 | BF25: < 0.049 | BG25: < 0.009 | BH25: < 0.027 | BI25: < 0.004 | BJ25: < 0.009 | BK25: < 0.009 | BL25: < 0.086 | BM25: < 0.009 | BN25: 0.024 | BO25: < 0.013 | BP25: < 0.014 | BQ25: < 0.029 | BR25: < 0.015 | BS25: < 0.009 | BT25: < 0.017 | BU25: < 0.010 | BV25: < 0.018 | BW25: < 0.027 | BX25: < 0.015 | BY25: < 0.099 | BZ25: < 0.023 | CA25: 67.270487 | CB25: 1.919 | CC25: 7.61 | CD25: 34.755 | CE25: 8.910215 | CF25: 84.245352 | CG25: 6.844433
A26: ST6_P21_1 | B26: ST6 | C26: SPRING_2021 | D26: FRESHWATER | E26: 1 | F26: 46.28213 | G26: -0.969368 | H26: 44293 | I26: 0.40277778 | J26: 9.2 | K26: 7.454 | L26: 0.7 | M26: =1.554*L26+0.4349 -> 1.5227 | N26: -42.5 | O26: 8.9 | P26: 6.2939785e+08 | Q26: 1.6666667 | R26: 2.8666667 | S26: 0.73333333 | T26: 7.2222222 | U26: 17.579085 | V26: 24.265431 | W26: =U26/(U26+V26)*100 -> 42.010487 | X26: 4401.87 | Y26: 8.64 | Z26: 0.1 | AA26: 6.95 | AB26: 23.8 | AC26: 12.25 | AD26: 19975.86 | AE26: 553.91 | AF26: 18.05 | AG26: 14.45 | AH26: < 0.4 | AI26: 29.48 | AJ26: 74.18 | AK26: 0.07 | AL26: 0 | AM26: 0.28 | AN26: 2.594 | AO26: 437.532 | AP26: 224.928 | AQ26: 43.586763 | AR26: < 0.008 | AS26: < 2.988 | AT26: < 0.061 | AU26: < 0.312 | AV26: < 0.015 | AW26: < 0.056 | AX26: < 2.376 | AY26: < 0.005 | AZ26: < 0.477 | BA26: < 0.040 | BB26: < 0.166 | BC26: < 0.004 | BD26: < 0.049 | BE26: < 0.048 | BF26: < 0.049 | BG26: < 0.009 | BH26: < 0.027 | BI26: < 0.004 | BJ26: < 0.008 | BK26: < 0.009 | BL26: < 0.068 | BM26: < 0.007 | BN26: < 0.068 | BO26: < 0.025 | BP26: < 0.009 | BQ26: < 0.027 | BR26: < 0.016 | BS26: < 0.009 | BT26: < 0.067 | BU26: < 0.010 | BV26: < 0.017 | BW26: < 0.029 | BX26: < 0.013 | BY26: < 0.097 | BZ26: 0.026 | CA26: 63.414797 | CB26: 3.569 | CC26: 113.444 | CD26: 1012.508 | CE26: 3.923251 | CF26: 38.433541 | CG26: 57.643209
A27: ST6_P21_2 | B27: ST6 | C27: SPRING_2021 | D27: FRESHWATER | E27: 2 | F27: 46.28213 | G27: -0.969368 | H27: 44293 | I27: 0.42708333 | J27: 10.7 | K27: 7.347 | L27: 0.7 | M27: =1.554*L27+0.4349 -> 1.5227 | N27: -36 | O27: 8.7 | P27: 6.3620675e+08 | Q27: 3.5666667 | R27: 4.3333333 | S27: 0.53333333 | T27: 9.1777778 | U27: 13.091661 | V27: 35.172262 | W27: =U27/(U27+V27)*100 -> 27.125148 | X27: 4450.58 | Y27: 8.81 | Z27: 0.1 | AA27: 6.86 | AB27: 26.44 | AC27: 10.48 | AD27: 22680.51 | AE27: 373.31 | AF27: 19.29 | AG27: 14.23 | AH27: < 0.39 | AI27: 31.24 | AJ27: 78.95 | AK27: 0.06 | AL27: 0 | AM27: 0.196 | AN27: 1.02 | AO27: 446.884 | AP27: 151.232 | AQ27: 35.77636 | AR27: < 0.008 | AS27: < 2.988 | AT27: < 0.061 | AU27: < 0.312 | AV27: < 0.015 | AW27: < 0.056 | AX27: < 2.376 | AY27: < 0.005 | AZ27: < 0.477 | BA27: < 0.040 | BB27: < 0.166 | BC27: < 0.004 | BD27: < 0.049 | BE27: < 0.048 | BF27: < 0.049 | BG27: < 0.009 | BH27: < 0.027 | BI27: < 0.004 | BJ27: < 0.008 | BK27: < 0.009 | BL27: < 0.068 | BM27: < 0.007 | BN27: < 0.068 | BO27: < 0.025 | BP27: < 0.009 | BQ27: < 0.027 | BR27: < 0.016 | BS27: < 0.009 | BT27: < 0.067 | BU27: < 0.010 | BV27: < 0.017 | BW27: < 0.029 | BX27: < 0.013 | BY27: < 0.097 | BZ27: 0.026 | CA27: 65.318785 | CB27: 2.003 | CC27: 8.423 | CD27: 44.289 | CE27: 8.331711 | CF27: 82.054848 | CG27: 9.613442
A28: ST6_P21_3 | B28: ST6 | C28: SPRING_2021 | D28: FRESHWATER | E28: 3 | F28: 46.28213 | G28: -0.969368 | H28: 44293 | I28: 0.40972222 | J28: 11 | K28: 7.393 | L28: 0.7 | M28: =1.554*L28+0.4349 -> 1.5227 | N28: -38.9 | O28: 6.9 | P28: 9.2601062e+08 | Q28: 1.6333333 | R28: 3.4333333 | S28: 0.66666667 | T28: 7.5333333 | U28: 21.810505 | V28: 23.283225 | W28: =U28/(U28+V28)*100 -> 48.367045 | X28: 4665.96 | Y28: 7.9 | Z28: 0.08 | AA28: 6.35 | AB28: 24.25 | AC28: 10.14 | AD28: 21677.2 | AE28: 363.7 | AF28: 17.87 | AG28: 12.96 | AH28: < 0.41 | AI28: 28.75 | AJ28: 70.35 | AK28: 0.06 | AL28: 0.298 | AM28: 0.318 | AN28: 1.396 | AO28: 282.168 | AP28: 149.604 | AQ28: 37.312762 | AR28: < 0.008 | AS28: < 2.988 | AT28: < 0.061 | AU28: < 0.312 | AV28: < 0.015 | AW28: < 0.056 | AX28: < 2.376 | AY28: < 0.005 | AZ28: < 0.477 | BA28: < 0.040 | BB28: < 0.166 | BC28: < 0.004 | BD28: < 0.049 | BE28: < 0.048 | BF28: < 0.049 | BG28: < 0.009 | BH28: < 0.027 | BI28: < 0.004 | BJ28: < 0.008 | BK28: < 0.009 | BL28: < 0.068 | BM28: < 0.007 | BN28: < 0.068 | BO28: < 0.025 | BP28: < 0.009 | BQ28: < 0.027 | BR28: < 0.016 | BS28: < 0.009 | BT28: < 0.067 | BU28: < 0.010 | BV28: < 0.017 | BW28: < 0.029 | BX28: < 0.013 | BY28: < 0.097 | BZ28: 0.026 | CA28: 52.406968 | CB28: 1.831 | CC28: 8.985 | CD28: 168.178 | CE28: 9.683883 | CF28: 69.547775 | CG28: 20.768343
A29: ST75_P21_1 | B29: St75 | C29: SPRING_2021 | D29: BRACKISH | E29: 1 | F29: 45.883995 | G29: -1.055508 | H29: 44294 | I29: 0.44791667 | J29: 10.8 | K29: 7.343 | L29: 2.1 | M29: =1.554*L29+0.4349 -> 3.6983 | N29: -36.4 | O29: 16 | P29: 1.9608732e+09 | Q29: 3.2 | R29: 20.4 | S29: 1.8666667 | T29: 28.4 | U29: 17.90954 | V29: 65.915149 | W29: =U29/(U29+V29)*100 -> 21.365471 | X29: 4855.88 | Y29: 21.07 | Z29: 0.11 | AA29: 8.7 | AB29: 29.8 | AC29: 15.02 | AD29: 28579.93 | AE29: 656.55 | AF29: 23.95 | AG29: 14.16 | AH29: < 0.4 | AI29: 45.83 | AJ29: 104.6 | AK29: 0.08 | AL29: 0 | AM29: 0.36 | AN29: 9.225 | AO29: 307.9 | AP29: 149.85 | AQ29: 46.883128 | AR29: < 0.019 | AS29: < 2.399 | AT29: < 0.059 | AU29: < 0.311 | AV29: < 0.019 | AW29: < 0.054 | AX29: < 2.502 | AY29: < 0.007 | AZ29: < 0.467 | BA29: < 0.029 | BB29: < 0.118 | BC29: < 0.004 | BD29: < 0.030 | BE29: < 0.048 | BF29: < 0.049 | BG29: < 0.010 | BH29: < 0.028 | BI29: < 0.004 | BJ29: < 0.009 | BK29: < 0.010 | BL29: < 0.087 | BM29: < 0.009 | BN29: 0.033 | BO29: < 0.013 | BP29: < 0.015 | BQ29: < 0.029 | BR29: < 0.015 | BS29: < 0.009 | BT29: < 0.017 | BU29: < 0.010 | BV29: < 0.018 | BW29: < 0.027 | BX29: < 0.015 | BY29: < 0.100 | BZ29: < 0.023 | CA29: 67.148511 | CB29: 1.993 | CC29: 9.491 | CD29: 51.857 | CE29: 8.41268 | CF29: 80.168641 | CG29: 11.418678
A30: ST75_P21_2 | B30: St75 | C30: SPRING_2021 | D30: BRACKISH | E30: 2 | F30: 45.883995 | G30: -1.055508 | H30: 44294 | I30: 0.43888889 | J30: 11 | K30: 7.228 | L30: 2 | M30: =1.554*L30+0.4349 -> 3.5429 | N30: -29.9 | O30: 18 | P30: 1.9396111e+09 | Q30: 3.2 | R30: 16.8 | S30: 2.2666667 | T30: 24.177778 | U30: 14.278071 | V30: 72.244269 | W30: =U30/(U30+V30)*100 -> 16.502178 | X30: 4944.7 | Y30: 18.78 | Z30: 0.1 | AA30: 8.76 | AB30: 28.44 | AC30: 14 | AD30: 26869.95 | AE30: 619.75 | AF30: 22.66 | AG30: 14.28 | AH30: < 0.4 | AI30: 43.89 | AJ30: 89.62 | AK30: 0.08 | AL30: 0 | AM30: 0.462 | AN30: 10.414 | AO30: 354.083 | AP30: 144.617 | AQ30: 64.289776 | AR30: < 0.019 | AS30: < 2.399 | AT30: < 0.059 | AU30: < 0.311 | AV30: < 0.019 | AW30: < 0.054 | AX30: < 2.502 | AY30: < 0.007 | AZ30: < 0.467 | BA30: < 0.029 | BB30: < 0.118 | BC30: < 0.004 | BD30: < 0.030 | BE30: < 0.048 | BF30: < 0.049 | BG30: < 0.010 | BH30: < 0.028 | BI30: < 0.004 | BJ30: < 0.009 | BK30: < 0.010 | BL30: < 0.087 | BM30: < 0.009 | BN30: 0.033 | BO30: < 0.013 | BP30: < 0.015 | BQ30: < 0.029 | BR30: < 0.015 | BS30: < 0.009 | BT30: < 0.017 | BU30: < 0.010 | BV30: < 0.018 | BW30: < 0.027 | BX30: < 0.015 | BY30: < 0.100 | BZ30: < 0.023 | CA30: 65.909756 | CB30: 2.073 | CC30: 8.446 | CD30: 84.946 | CE30: 7.8165 | CF30: 77.493976 | CG30: 14.689523
A31: ST75_P21_3 | B31: St75 | C31: SPRING_2021 | D31: BRACKISH | E31: 3 | F31: 45.883995 | G31: -1.055508 | H31: 44294 | I31: 0.4125 | J31: 10.7 | K31: 7.28 | L31: 2 | M31: =1.554*L31+0.4349 -> 3.5429 | N31: -33 | O31: 18 | P31: 1.6505101e+09 | Q31: 2.1333333 | R31: 19.866667 | S31: 0.93333333 | T31: 24.222222 | U31: 21.760633 | V31: 54.076471 | W31: =U31/(U31+V31)*100 -> 28.693913 | X31: 5021.68 | Y31: 19.64 | Z31: 0.1 | AA31: 8.88 | AB31: 31.03 | AC31: 14.39 | AD31: 29365.85 | AE31: 647.61 | AF31: 23.86 | AG31: 13.89 | AH31: < 0.4 | AI31: 44.04 | AJ31: 93.07 | AK31: 0.08 | AL31: 0 | AM31: 0.303 | AN31: 4.594 | AO31: 362.506 | AP31: 155.958 | AQ31: 43.868396 | AR31: < 0.019 | AS31: < 2.399 | AT31: < 0.059 | AU31: < 0.311 | AV31: < 0.019 | AW31: < 0.054 | AX31: < 2.502 | AY31: < 0.007 | AZ31: < 0.467 | BA31: < 0.029 | BB31: < 0.118 | BC31: < 0.004 | BD31: < 0.030 | BE31: < 0.048 | BF31: < 0.049 | BG31: < 0.010 | BH31: < 0.028 | BI31: < 0.004 | BJ31: < 0.009 | BK31: < 0.010 | BL31: < 0.087 | BM31: < 0.009 | BN31: 0.033 | BO31: < 0.013 | BP31: < 0.015 | BQ31: < 0.029 | BR31: < 0.015 | BS31: < 0.009 | BT31: < 0.017 | BU31: < 0.010 | BV31: < 0.018 | BW31: < 0.027 | BX31: < 0.015 | BY31: < 0.100 | BZ31: < 0.023 | CA31: 67.792783 | CB31: 1.818 | CC31: 7.6 | CD31: 39.043 | CE31: 9.78876 | CF31: 81.750908 | CG31: 8.460333
A32: ST16_P21_1 | B32: ST16 | C32: SPRING_2021 | D32: SALTED | E32: 1 | F32: 46.23537 | G32: -1.514997 | H32: 44298 | I32: 0.42291667 | J32: 11.1 | K32: 7.445 | L32: 33.9 | M32: =1.554*L32+0.4349 -> 53.1155 | N32: -40.7 | O32: 8 | P32: 1.0837958e+10 | Q32: 174.53333 | R32: 4 | S32: 0.93333333 | T32: 180.31111 | U32: 16.67511 | V32: 28.072857 | W32: =U32/(U32+V32)*100 -> 37.264509 | X32: 4301.97 | Y32: 10.99 | Z32: 0.12 | AA32: 4.06 | AB32: 18.54 | AC32: 9.49 | AD32: 15004.82 | AE32: 200.29 | AF32: 10.98 | AG32: 10.33 | AH32: < 0.4 | AI32: 26.27 | AJ32: 59.59 | AK32: 0.06 | AL32: 0 | AM32: 1.402 | AN32: 14.906 | AO32: 142.552 | AP32: 130.336 | AQ32: 34.52309 | AR32: 0.009 | AS32: < 2.794 | AT32: < 0.057 | AU32: < 0.292 | AV32: < 0.014 | AW32: < 0.052 | AX32: < 2.222 | AY32: < 0.005 | AZ32: < 0.446 | BA32: < 0.037 | BB32: < 0.155 | BC32: < 0.004 | BD32: < 0.046 | BE32: < 0.045 | BF32: 0.068 | BG32: < 0.009 | BH32: < 0.025 | BI32: < 0.004 | BJ32: < 0.007 | BK32: < 0.009 | BL32: < 0.064 | BM32: < 0.007 | BN32: < 0.063 | BO32: < 0.024 | BP32: 0.01 | BQ32: < 0.025 | BR32: < 0.015 | BS32: < 0.008 | BT32: < 0.063 | BU32: 0.03 | BV32: < 0.016 | BW32: < 0.027 | BX32: < 0.012 | BY32: < 0.091 | BZ32: < 0.015 | CA32: 47.641596 | CB32: 2.486 | CC32: 10.581 | CD32: 133.865 | CE32: 5.769831 | CF32: 68.995128 | CG32: 25.23504
A33: ST16_P21_2 | B33: ST16 | C33: SPRING_2021 | D33: SALTED | E33: 2 | F33: 46.23537 | G33: -1.514997 | H33: 44298 | I33: 0.42708333 | J33: 10 | K33: 7.841 | L33: 33.6 | M33: =1.554*L33+0.4349 -> 52.6493 | N33: -62.5 | O33: 6.6 | P33: 1.8466291e+09 | Q33: 116.53333 | R33: 4.8 | S33: 2.1333333 | T33: 125.6 | U33: 4.1701863 | V33: 6.2030122 | W33: =U33/(U33+V33)*100 -> 40.201547 | X33: 4243.43 | Y33: 14.34 | Z33: 0.09 | AA33: 4.03 | AB33: 16.31 | AC33: 7.44 | AD33: 15860.23 | AE33: 215.63 | AF33: 11.07 | AG33: 9.18 | AH33: < 0.4 | AI33: 26.04 | AJ33: 41.65 | AK33: 0.04 | AL33: 0.856 | AM33: 0.764 | AN33: 4.02 | AO33: 103.1 | AP33: 29.308 | AQ33: 40.782847 | AR33: 0.009 | AS33: < 2.794 | AT33: < 0.057 | AU33: < 0.292 | AV33: < 0.014 | AW33: < 0.052 | AX33: < 2.222 | AY33: < 0.005 | AZ33: < 0.446 | BA33: < 0.037 | BB33: < 0.155 | BC33: < 0.004 | BD33: < 0.046 | BE33: < 0.045 | BF33: 0.068 | BG33: < 0.009 | BH33: < 0.025 | BI33: < 0.004 | BJ33: < 0.007 | BK33: < 0.009 | BL33: < 0.064 | BM33: < 0.007 | BN33: < 0.063 | BO33: < 0.024 | BP33: 0.01 | BQ33: < 0.025 | BR33: < 0.015 | BS33: < 0.008 | BT33: < 0.063 | BU33: 0.03 | BV33: < 0.016 | BW33: < 0.027 | BX33: < 0.012 | BY33: < 0.091 | BZ33: < 0.015 | CA33: 40.443274 | CB33: 2.179 | CC33: 10.157 | CD33: 121.439 | CE33: 7.295182 | CF33: 66.36494 | CG33: 26.339876
A34: ST16_P21_3 | B34: ST16 | C34: SPRING_2021 | D34: SALTED | E34: 3 | F34: 46.23537 | G34: -1.514997 | H34: 44298 | I34: 0.43055556 | J34: 10.2 | K34: 7.548 | L34: 34.3 | M34: =1.554*L34+0.4349 -> 53.7371 | N34: -46.8 | O34: 7.9 | P34: 1.1247967e+10 | Q34: 111.2 | R34: 7.2 | S34: 3.2 | T34: 124.8 | U34: 17.235072 | V34: 16.646987 | W34: =U34/(U34+V34)*100 -> 50.86784 | X34: 3962.06 | Y34: 8.22 | Z34: 0.11 | AA34: 3.13 | AB34: 14.54 | AC34: 7.08 | AD34: 11880.85 | AE34: 177.61 | AF34: 8.22 | AG34: 9.06 | AH34: < 0.4 | AI34: 20.43 | AJ34: 46.88 | AK34: 0.04 | AL34: 0.302 | AM34: 1.248 | AN34: 25.844 | AO34: 162.274 | AP34: 167.808 | AQ34: 43.671348 | AR34: 0.009 | AS34: < 2.794 | AT34: < 0.057 | AU34: < 0.292 | AV34: < 0.014 | AW34: < 0.052 | AX34: < 2.222 | AY34: < 0.005 | AZ34: < 0.446 | BA34: < 0.037 | BB34: < 0.155 | BC34: < 0.004 | BD34: < 0.046 | BE34: < 0.045 | BF34: 0.068 | BG34: < 0.009 | BH34: < 0.025 | BI34: < 0.004 | BJ34: < 0.007 | BK34: < 0.009 | BL34: < 0.064 | BM34: < 0.007 | BN34: < 0.063 | BO34: < 0.024 | BP34: 0.01 | BQ34: < 0.025 | BR34: < 0.015 | BS34: < 0.008 | BT34: < 0.063 | BU34: 0.03 | BV34: < 0.016 | BW34: < 0.027 | BX34: < 0.012 | BY34: < 0.091 | BZ34: < 0.015 | CA34: 49.671003 | CB34: 2.333 | CC34: 14.098 | CD34: 146.066 | CE34: 6.642665 | CF34: 59.627681 | CG34: 33.729655
A35: ST13_P21_1 | B35: ST13 | C35: SPRING_2021 | D35: BRACKISH | E35: 1 | F35: 46.262243 | G35: -1.106867 | H35: 44298 | I35: 0.52083333 | J35: 12.5 | K35: 7.437 | L35: 9.2 | M35: =1.554*L35+0.4349 -> 14.7317 | N35: -40.5 | O35: 6.2 | P35: 5.2397492e+09 | Q35: 14.2 | R35: 24.466667 | S35: 1.1333333 | T35: 41.488889 | U35: 22.388794 | V35: 34.29529 | W35: =U35/(U35+V35)*100 -> 39.497496 | X35: 5256.84 | Y35: 17.3 | Z35: 0.11 | AA35: 7.87 | AB35: 30.43 | AC35: 14.56 | AD35: 27627.42 | AE35: 703.58 | AF35: 21.91 | AG35: 14.96 | AH35: < 0.41 | AI35: 43.37 | AJ35: 100.64 | AK35: 0.07 | AL35: 0.052 | AM35: 0.576 | AN35: 3.584 | AO35: 211.158 | AP35: 184.326 | AQ35: 51.928438 | AR35: < 0.008 | AS35: < 3.048 | AT35: < 0.062 | AU35: < 0.319 | AV35: < 0.015 | AW35: < 0.057 | AX35: < 2.424 | AY35: < 0.005 | AZ35: < 0.486 | BA35: < 0.040 | BB35: < 0.169 | BC35: < 0.005 | BD35: < 0.050 | BE35: < 0.049 | BF35: 0.082 | BG35: < 0.010 | BH35: < 0.028 | BI35: < 0.004 | BJ35: < 0.008 | BK35: < 0.009 | BL35: < 0.070 | BM35: < 0.007 | BN35: 0.08 | BO35: < 0.026 | BP35: 0.017 | BQ35: < 0.028 | BR35: < 0.017 | BS35: < 0.009 | BT35: < 0.069 | BU35: 0.053 | BV35: < 0.018 | BW35: 0.051 | BX35: < 0.014 | BY35: < 0.099 | BZ35: < 0.016 | CA35: 63.711459 | CB35: 1.761 | CC35: 7.791 | CD35: 54.717 | CE35: 10.312037 | CF35: 78.266147 | CG35: 11.421816
A36: ST13_P21_2 | B36: ST13 | C36: SPRING_2021 | D36: BRACKISH | E36: 2 | F36: 46.262243 | G36: -1.106867 | H36: 44298 | I36: 0.53055556 | J36: 12.6 | K36: 7.451 | L36: 9.1 | M36: =1.554*L36+0.4349 -> 14.5763 | N36: -40.3 | O36: 6.5 | P36: 5.279939e+09 | Q36: 5.5333333 | R36: 3.0666667 | S36: 0.2 | T36: 9.5333333 | U36: 27.179894 | V36: 42.217 | W36: =U36/(U36+V36)*100 -> 39.165866 | X36: 5241.46 | Y36: 19.87 | Z36: 0.1 | AA36: 8.17 | AB36: 30.89 | AC36: 15.02 | AD36: 29003.96 | AE36: 582.86 | AF36: 22.79 | AG36: 14.48 | AH36: < 0.4 | AI36: 43.21 | AJ36: 97.81 | AK36: 0.07 | AL36: 0.118 | AM36: 0.482 | AN36: 3.954 | AO36: 226.218 | AP36: 221.594 | AQ36: 42.505901 | AR36: < 0.008 | AS36: < 3.048 | AT36: < 0.062 | AU36: < 0.319 | AV36: < 0.015 | AW36: < 0.057 | AX36: < 2.424 | AY36: < 0.005 | AZ36: < 0.486 | BA36: < 0.040 | BB36: < 0.169 | BC36: < 0.005 | BD36: < 0.050 | BE36: < 0.049 | BF36: 0.082 | BG36: < 0.010 | BH36: < 0.028 | BI36: < 0.004 | BJ36: < 0.008 | BK36: < 0.009 | BL36: < 0.070 | BM36: < 0.007 | BN36: 0.08 | BO36: < 0.026 | BP36: 0.017 | BQ36: < 0.028 | BR36: < 0.017 | BS36: < 0.009 | BT36: < 0.069 | BU36: 0.053 | BV36: < 0.018 | BW36: 0.051 | BX36: < 0.014 | BY36: < 0.099 | BZ36: < 0.016 | CA36: 64.444836 | CB36: 1.795 | CC36: 7.11 | CD36: 27.464 | CE36: 10.000335 | CF36: 85.976727 | CG36: 4.022935
A37: ST13_P21_3 | B37: ST13 | C37: SPRING_2021 | D37: BRACKISH | E37: 3 | F37: 46.262243 | G37: -1.106867 | H37: 44298 | I37: 0.53819444 | J37: 13 | K37: 7.43 | L37: 6.8 | M37: =1.554*L37+0.4349 -> 11.0021 | N37: -40.5 | O37: 5.5 | P37: 3.8895254e+09 | Q37: 4.4 | R37: 23.066667 | S37: 1.8 | T37: 30 | U37: 11.52348 | V37: 25.84964 | W37: =U37/(U37+V37)*100 -> 30.833605 | X37: 5083.06 | Y37: 18.81 | Z37: 0.1 | AA37: 7.67 | AB37: 29.71 | AC37: 13.56 | AD37: 26922.48 | AE37: 734.73 | AF37: 21.74 | AG37: 13.81 | AH37: < 0.39 | AI37: 41.91 | AJ37: 88.21 | AK37: 0.06 | AL37: 0 | AM37: 0.404 | AN37: 1.902 | AO37: 246.452 | AP37: 142.336 | AQ37: 37.940317 | AR37: < 0.008 | AS37: < 3.048 | AT37: < 0.062 | AU37: < 0.319 | AV37: < 0.015 | AW37: < 0.057 | AX37: < 2.424 | AY37: < 0.005 | AZ37: < 0.486 | BA37: < 0.040 | BB37: < 0.169 | BC37: < 0.005 | BD37: < 0.050 | BE37: < 0.049 | BF37: 0.082 | BG37: < 0.010 | BH37: < 0.028 | BI37: < 0.004 | BJ37: < 0.008 | BK37: < 0.009 | BL37: < 0.070 | BM37: < 0.007 | BN37: 0.08 | BO37: < 0.026 | BP37: 0.017 | BQ37: < 0.028 | BR37: < 0.017 | BS37: < 0.009 | BT37: < 0.069 | BU37: 0.053 | BV37: < 0.018 | BW37: 0.051 | BX37: < 0.014 | BY37: < 0.099 | BZ37: < 0.016 | CA37: 60.356752 | CB37: 1.768 | CC37: 8.689 | CD37: 97.85 | CE37: 10.241711 | CF37: 73.913161 | CG37: 15.84513
A38: ST52_P21_1 | B38: ST52 | C38: SPRING_2021 | D38: SALTED | E38: 1 | F38: 45.961839 | G38: -1.278105 | H38: 44299 | I38: 0.47638889 | J38: 11.4 | K38: 7.666 | L38: 29.7 | M38: =1.554*L38+0.4349 -> 46.5887 | N38: -52 | O38: 9.6 | P38: 4.0151242e+09 | Q38: 63.2 | R38: 2.6666667 | S38: 2.1333333 | T38: 69.822222 | U38: 8.4272413 | V38: 13.533933 | W38: =U38/(U38+V38)*100 -> 38.373364 | X38: 4868.49 | Y38: 13.19 | Z38: 0.07 | AA38: 4.9 | AB38: 20.79 | AC38: 12.55 | AD38: 19521.83 | AE38: 287.66 | AF38: 14.31 | AG38: 14.85 | AH38: < 0.39 | AI38: 27.38 | AJ38: 68.19 | AK38: 0.05 | AL38: 0.066 | AM38: 0.339 | AN38: 1.89 | AO38: 96.626 | AP38: 35.417 | AQ38: 32.663975 | AR38: < 0.008 | AS38: < 2.874 | AT38: < 0.058 | AU38: < 0.300 | AV38: < 0.014 | AW38: < 0.054 | AX38: < 2.285 | AY38: < 0.005 | AZ38: < 0.459 | BA38: < 0.038 | BB38: < 0.159 | BC38: < 0.004 | BD38: 0.063 | BE38: < 0.046 | BF38: 0.147 | BG38: < 0.009 | BH38: < 0.026 | BI38: < 0.004 | BJ38: < 0.008 | BK38: < 0.009 | BL38: < 0.066 | BM38: < 0.007 | BN38: 0.143 | BO38: < 0.024 | BP38: 0.042 | BQ38: 0.039 | BR38: < 0.016 | BS38: < 0.008 | BT38: < 0.065 | BU38: 0.092 | BV38: < 0.017 | BW38: 0.155 | BX38: < 0.013 | BY38: < 0.094 | BZ38: < 0.015 | CA38: 51.726287 | CB38: 2.164 | CC38: 12.18 | CD38: 130.864 | CE38: 7.312817 | CF38: 63.767315 | CG38: 28.919865
A39: ST52_P21_2 | B39: ST52 | C39: SPRING_2021 | D39: SALTED | E39: 2 | F39: 45.961839 | G39: -1.278105 | H39: 44299 | I39: 0.49166667 | J39: 11 | K39: 7.699 | L39: 29.9 | M39: =1.554*L39+0.4349 -> 46.8995 | N39: -53.8 | O39: 8.5 | P39: 4.0742765e+09 | Q39: 68.4 | R39: 1.4666667 | S39: 1.4666667 | T39: 73.688889 | U39: 10.934991 | V39: 14.740191 | W39: =U39/(U39+V39)*100 -> 42.589733 | X39: 5077.7 | Y39: 12.23 | Z39: 0.06 | AA39: 4.5 | AB39: 20.48 | AC39: 11.29 | AD39: 18916.99 | AE39: 310.1 | AF39: 14.21 | AG39: 11.05 | AH39: < 0.41 | AI39: 27.39 | AJ39: 68.93 | AK39: 0.05 | AL39: 0 | AM39: 1.128 | AN39: 4.954 | AO39: 121.04 | AP39: 51.466 | AQ39: 41.275878 | AR39: < 0.008 | AS39: < 2.874 | AT39: < 0.058 | AU39: < 0.300 | AV39: < 0.014 | AW39: < 0.054 | AX39: < 2.285 | AY39: < 0.005 | AZ39: < 0.459 | BA39: < 0.038 | BB39: < 0.159 | BC39: < 0.004 | BD39: 0.063 | BE39: < 0.046 | BF39: 0.147 | BG39: < 0.009 | BH39: < 0.026 | BI39: < 0.004 | BJ39: < 0.008 | BK39: < 0.009 | BL39: < 0.066 | BM39: < 0.007 | BN39: 0.143 | BO39: < 0.024 | BP39: 0.042 | BQ39: 0.039 | BR39: < 0.016 | BS39: < 0.008 | BT39: < 0.065 | BU39: 0.092 | BV39: < 0.017 | BW39: 0.155 | BX39: < 0.013 | BY39: < 0.094 | BZ39: < 0.015 | CA39: 48.961515 | CB39: 2.358 | CC39: 12.082 | CD39: 121.772 | CE39: 6.362219 | CF39: 65.529058 | CG39: 28.108724
A40: ST52_P21_3 | B40: ST52 | C40: SPRING_2021 | D40: SALTED | E40: 3 | F40: 45.961839 | G40: -1.278105 | H40: 44299 | I40: 0.51388889 | J40: 12.5 | K40: 7.648 | L40: 31.8 | M40: =1.554*L40+0.4349 -> 49.8521 | N40: -51.7 | O40: 7.7 | P40: 6.2178039e+09 | Q40: 75.066667 | R40: 3.0666667 | S40: 0.8 | T40: 81.6 | U40: 9.9650407 | V40: 16.521928 | W40: =U40/(U40+V40)*100 -> 37.622428 | X40: 5247.69 | Y40: 13.61 | Z40: 0.07 | AA40: 5 | AB40: 21.61 | AC40: 12.04 | AD40: 19651.02 | AE40: 323.08 | AF40: 14.97 | AG40: 14.07 | AH40: < 0.41 | AI40: 29.47 | AJ40: 72.08 | AK40: 0.06 | AL40: 0.028 | AM40: 0.738 | AN40: 3.13 | AO40: 99.958 | AP40: 44.816 | AQ40: 32.865188 | AR40: < 0.008 | AS40: < 2.874 | AT40: < 0.058 | AU40: < 0.300 | AV40: < 0.014 | AW40: < 0.054 | AX40: < 2.285 | AY40: < 0.005 | AZ40: < 0.459 | BA40: < 0.038 | BB40: < 0.159 | BC40: < 0.004 | BD40: 0.063 | BE40: < 0.046 | BF40: 0.147 | BG40: < 0.009 | BH40: < 0.026 | BI40: < 0.004 | BJ40: < 0.008 | BK40: < 0.009 | BL40: < 0.066 | BM40: < 0.007 | BN40: 0.143 | BO40: < 0.024 | BP40: 0.042 | BQ40: 0.039 | BR40: < 0.016 | BS40: < 0.008 | BT40: < 0.065 | BU40: 0.092 | BV40: < 0.017 | BW40: 0.155 | BX40: < 0.013 | BY40: < 0.094 | BZ40: < 0.015 | CA40: 47.77983 | CB40: 2.11 | CC40: 8.852 | CD40: 80.138 | CE40: 7.585194 | CF40: 75.13928 | CG40: 17.275526
...

Sheet MOYENNES
A1: Sample | B1: Site | C1: Season | D1: Typology | E1: Localisation_X | F1: Localisation_Y | G1: Date | H1: Heure | I1: Sediment_temperature | J1: pH | K1: Salinity | L1: Conductivity | M1: RedOx | N1: COD | O1: Bacteria | P1: Nematoda | Q1: Copepoda | R1: Ostracoda | S1: Total_meiofauna | T1: Chlorophyll_a | U1: Pheopigment | V1: Active_chlorophyll_a | W1: Al | X1: As | Y1: Cd | Z1: Co | AA1: Cr | AB1: Cu | AC1: Fe | AD1: Mn | AE1: Ni | AF1: Pb | AG1: Se | AH1: V | AI1: Zn | AJ1: Ag | AK1: NO3 | AL1: NO2 | AM1: PO4 | AN1: Si | AO1: NH4 | AP1: Total_Hydrocarbon | AQ1: 1,3,5-TriCB | AR1: 1,2,4-TriCB | AS1: 1,2,3-TriCB | AT1: HCBD | AU1: Dichlorvos | AV1: PeCBz | AW1: a-HCH | AX1: HCB | AY1: g-HCH | AZ1: b-HCH | BA1: d-HCH | BB1: Heptachlor | BC1: 2,4'-Dicofol | BD1: oxychlordane | BE1: 4,4'-Dicofol | BF1: Heptachlor epoxyde cis | BG1: Heptachlor epoxyde trans | BH1: o,p-DDE | BI1: g-chlordane | BJ1: Trans nanochlor | BK1: a-endosulfan | BL1: a-chlordane | BM1: p,p-DDE | BN1: Dieldrin | BO1: o,p-DDD | BP1: o,p-DDT | BQ1: Endrin | BR1: cis-nanochlor | BS1: b-endosulfan | BT1: p,p-DDD | BU1: quinoxyfen | BV1: p,p-DDT | BW1: endosulfan sulfate | BX1: mirex | BY1: cypermethrine | BZ1: Water_content | CA1: D10 | CB1: D50 | CC1: D90 | CD1: Clay | CE1: Silt | CF1: Sand
A2: ST6_A20 | B2: ST6 | C2: AUTUMN_2020 | D2: FRESHWATER | E2: 46.28213 | F2: -0.969368 | G2: 44167 | H2: 0.36111111 | I2: =AVERAGE(ALL_DATA!J2:J4) -> 6.2666667 | J2: =AVERAGE(ALL_DATA!K2:K4) -> 7.461 | K2: =AVERAGE(ALL_DATA!L2:L4) -> 0.53333333 | L2: =AVERAGE(ALL_DATA!M2:M4) -> 1.2333333 | M2: =AVERAGE(ALL_DATA!N2:N4) -> -22.466667 | N2: =AVERAGE(ALL_DATA!O2:O4) -> 7 | O2: =AVERAGE(ALL_DATA!P2:P4) -> 8.118704e+08 | P2: =AVERAGE(ALL_DATA!Q2:Q4) -> 1.8555556 | ... AP2: =AVERAGE(ALL_DATA!AQ2:AQ4) -> 28.621132 | AQ2: NA | AR2: NA | AS2: NA | AT2: NA | AU2: NA | AV2: NA | AW2: NA | AX2: NA | AY2: NA | AZ2: NA | BA2: NA | BB2: NA | BC2: NA | BD2: NA | BE2: NA | BF2: NA | BG2: NA | BH2: NA | BI2: NA | BJ2: NA | BK2: NA | BL2: NA | BM2: NA | BN2: NA | BO2: NA | BP2: NA | BQ2: NA | BR2: NA | BS2: NA | BT2: NA | BU2: NA | BV2: NA | BW2: NA | BX2: NA | BY2: =AVERAGE(ALL_DATA!BZ2:BZ4) -> 0.026 | BZ2: =AVERAGE(ALL_DATA!CA2:CA4) -> 57.234224 | CA2: =AVERAGE(ALL_DATA!CB2:CB4) -> 2.4676667 | CB2: =AVERAGE(ALL_DATA!CC2:CC4) -> 43.617333 | CC2: =AVERAGE(ALL_DATA!CD2:CD4) -> 408.325 | CD2: =AVERAGE(ALL_DATA!CE2:CE4) -> 7.3129483 | CE2: =AVERAGE(ALL_DATA!CF2:CF4) -> 63.345388 | CF2: =AVERAGE(ALL_DATA!CG2:CG4) -> 29.341665
A3: ST75_A20 | B3: ST75 | C3: AUTUMN_2020 | D3: BRACKISH | E3: 45.883995 | F3: -1.055508 | G3: 44168 | H3: 0.41666667 | I3: =AVERAGE(ALL_DATA!J5:J7) -> 7.4333333 | J3: =AVERAGE(ALL_DATA!K5:K7) -> 7.2766667 | K3: =AVERAGE(ALL_DATA!L5:L7) -> 2.4333333 | L3: =AVERAGE(ALL_DATA!M5:M7) -> 4.6133333 | M3: =AVERAGE(ALL_DATA!N5:N7) -> -12.433333 | N3: =AVERAGE(ALL_DATA!O5:O7) -> 16 | O3: =AVERAGE(ALL_DATA!P5:P7) -> 9.0281677e+08 | P3: =AVERAGE(ALL_DATA!Q5:Q7) -> 4.0222222 | ... AP3: =AVERAGE(ALL_DATA!AQ5:AQ7) -> 33.340232 | AQ3: NA | AR3: NA | AS3: NA | AT3: NA | AU3: NA | AV3: NA | AW3: NA | AX3: NA | AY3: NA | AZ3: NA | BA3: NA | BB3: NA | BC3: NA | BD3: NA | BE3: NA | BF3: NA | BG3: NA | BH3: NA | BI3: NA | BJ3: NA | BK3: NA | BL3: NA | BM3: =AVERAGE(ALL_DATA!BN5:BN7) -> 0.033 | BN3: NA | BO3: NA | BP3: NA | BQ3: NA | BR3: NA | BS3: NA | BT3: NA | BU3: NA | BV3: NA | BW3: NA | BX3: NA | BY3: NA | BZ3: =AVERAGE(ALL_DATA!CA5:CA7) -> 67.283821 | CA3: =AVERAGE(ALL_DATA!CB5:CB7) -> 1.9613333 | CB3: =AVERAGE(ALL_DATA!CC5:CC7) -> 8.5123333 | CC3: =AVERAGE(ALL_DATA!CD5:CD7) -> 58.615333 | CD3: =AVERAGE(ALL_DATA!CE5:CE7) -> 8.6726467 | CE3: =AVERAGE(ALL_DATA!CF5:CF7) -> 79.804508 | CF3: =AVERAGE(ALL_DATA!CG5:CG7) -> 11.522845
A4: ST16_A20 | B4: ST16 | C4: AUTUMN_2020 | D4: SALTED | E4: 46.23537 | F4: -1.514997 | G4: 44162 | H4: 0.38888889 | I4: =AVERAGE(ALL_DATA!J8:J10) -> 10.266667 | J4: =AVERAGE(ALL_DATA!K8:K10) -> 7.584 | K4: =AVERAGE(ALL_DATA!L8:L10) -> 31.1 | L4: =AVERAGE(ALL_DATA!M8:M10) -> 48.4 | M4: =AVERAGE(ALL_DATA!N8:N10) -> -29.666667 | N4: =AVERAGE(ALL_DATA!O8:O10) -> 9.8666667 | O4: =AVERAGE(ALL_DATA!P8:P10) -> 1.7664515e+09 | P4: =AVERAGE(ALL_DATA!Q8:Q10) -> 36.177778 | ... AQ4: =AVERAGE(ALL_DATA!AR8:AR10) -> 0.009 | AR4: NA | AS4: NA | AT4: NA | AU4: NA | AV4: NA | AW4: NA | AX4: NA | AY4: NA | AZ4: NA | BA4: NA | BB4: NA | BC4: NA | BD4: NA | BE4: =AVERAGE(ALL_DATA!BF8:BF10) -> 0.068 | BF4: NA | BG4: NA | BH4: NA | BI4: NA | BJ4: NA | BK4: NA | BL4: NA | BM4: NA | BN4: NA | BO4: =AVERAGE(ALL_DATA!BP8:BP10) -> 0.01 | BP4: NA | BQ4: NA | BR4: NA | BS4: NA | BT4: =AVERAGE(ALL_DATA!BU8:BU10) -> 0.03 | BU4: NA | BV4: NA | BW4: NA | BX4: NA | BY4: NA | BZ4: =AVERAGE(ALL_DATA!CA8:CA10) -> 41.038704 | CA4: =AVERAGE(ALL_DATA!CB8:CB10) -> 2.3326667 | CB4: =AVERAGE(ALL_DATA!CC8:CC10) -> 11.612 | CC4: =AVERAGE(ALL_DATA!CD8:CD10) -> 133.79 | CD4: =AVERAGE(ALL_DATA!CE8:CE10) -> 6.569226 | CE4: =AVERAGE(ALL_DATA!CF8:CF10) -> 64.995916 | CF4: =AVERAGE(ALL_DATA!CG8:CG10) -> 28.434857
